<mujocoinclude>
    <option cone="elliptic" impratio="10"/>

    <default>
        <default class="hande">
            <default class="hande_right_finger">
                <joint type="slide" range="0 0.025" actuatorfrcrange="-100 100" />
            </default>
            <default class="hande_left_finger">
                <joint type="slide" range="0 0.025" actuatorfrcrange="-100 100" />
            </default>
        </default>
    </default>

    <default>
        <joint damping="0.1" limited="true" />
        <geom friction="1.0 1.0 1.0" density="1000" margin="0.001" />
    </default>

    <visual>
        <global azimuth="120" elevation="-20" />
        <headlight diffuse="0.6 0.6 0.6" specular="0 0 0" />
        <rgba haze="0.15 0.25 0.35 1" />
    </visual>

    <statistic meansize="0.1" extent="1" center="4 0 0" />

    <worldbody>
        <body name="iiwa_world" pos="0 0 0">
            <!-- robot view -->
            <camera mode="fixed" name="iiwa_robotview" pos="1.0 0 0.4" quat="0.653 0.271 0.271 0.653"/>
            <body name="iiwa_link_0" pos="0 0 0">
                <inertial pos="0 0 0" mass="5" fullinertia="0.05 0.06 0.03 0 0 0" />
                <geom type="mesh" contype="0" conaffinity="0" group="1" mesh="iiwa_link_0_vis" name="iiwa_link_0_visual" rgba="0.4 0.4 0.4 1.0" />
                <geom type="mesh" group="0" mesh="iiwa_link_0" name="iiwa_link_0_collision"/>
                <body name="iiwa_link_1" pos="0 0 0.1575">
                    <inertial pos="0 -0.03 0.12" mass="4" fullinertia="0.1 0.09 0.02 0 0 0" />
                    <joint name="iiwa_joint_1" pos="0 0 0" axis="0 0 1" limited="true" range="-2.9670597283903604 2.9670597283903604" damping="0.5"/>
                    <geom type="mesh" contype="0" conaffinity="0" group="1" mesh="iiwa_link_1_vis" name="iiwa_link_1_visual" rgba="1.0 0.4235294117647059 0.0392156862745098 1.0" />
                    <geom type="mesh" group="0" mesh="iiwa_link_1" name="iiwa_link_1_collision"/>
                    <body name="iiwa_link_2" pos="0 0 0.2025" quat="0 0 0.7071068 0.7071068">
                        <inertial pos="0.0003 0.059 0.042" mass="4" fullinertia="0.05 0.018 0.044 0 0 0" />
                        <joint name="iiwa_joint_2" pos="0 0 0" axis="0 0 1" limited="true" range="-2.0943951023931953 2.0943951023931953" damping="0.5"/>
                        <geom type="mesh" contype="0" conaffinity="0" group="1" mesh="iiwa_link_2_vis" name="iiwa_link_2_visual" rgba="1.0 0.4235294117647059 0.0392156862745098 1.0" />
                        <geom type="mesh" group="0" mesh="iiwa_link_2" name="iiwa_link_2_collision"/>
                        <body name="iiwa_link_3" pos="0 0.2045 0" quat="0 0 0.7071068 0.7071068">
                            <inertial pos="0 0.03 0.13" mass="3" fullinertia="0.08 0.075 0.01 0 0 0" />
                            <joint name="iiwa_joint_3" pos="0 0 0" axis="0 0 1" limited="true" range="-2.9670597283903604 2.9670597283903604" damping="0.5"/>
                            <geom type="mesh" contype="0" conaffinity="0" group="1" mesh="iiwa_link_3_vis" name="iiwa_link_3_visual" rgba="1.0 0.4235294117647059 0.0392156862745098 1.0" />
                            <geom type="mesh" group="0" mesh="iiwa_link_3" name="iiwa_link_3_collision"/>
                            <body name="iiwa_link_4" pos="0 0 0.2155" quat="0.7071068 0.7071068 0 0">
                                <inertial pos="0 0.067 0.034" mass="2.7" fullinertia="0.03 0.01 0.029 0 0 0" />
                                <joint name="iiwa_joint_4" pos="0 0 0" axis="0 0 1" limited="true" range="-2.0943951023931953 2.0943951023931953" damping="0.5"/>
                                <geom type="mesh" contype="0" conaffinity="0" group="1" mesh="iiwa_link_4_vis" name="iiwa_link_4_visual" rgba="1.0 0.4235294117647059 0.0392156862745098 1.0" />
                                <geom type="mesh" group="0" mesh="iiwa_link_4" name="iiwa_link_4_collision"/>
                                <body name="iiwa_link_5" pos="0 0.1845 0" quat="0 0 0.7071068 0.7071068">
                                    <inertial pos="0.0001 0.021 0.076" mass="1.7" fullinertia="0.02 0.018 0.005 0 0 0" />
                                    <joint name="iiwa_joint_5" pos="0 0 0" axis="0 0 1" limited="true" range="-2.9670597283903604 2.9670597283903604" damping="0.5"/>
                                    <geom type="mesh" contype="0" conaffinity="0" group="1" mesh="iiwa_link_5_vis" name="iiwa_link_5_visual" rgba="1.0 0.4235294117647059 0.0392156862745098 1.0" />
                                    <geom type="mesh" group="0" mesh="iiwa_link_5" name="iiwa_link_5_collision"/>
                                    <body name="iiwa_link_6" pos="0 0 0.2155" quat="0.7071068 0.7071068 0 0">
                                        <inertial pos="0 0.0006 0.0004" mass="1.8" fullinertia="0.005 0.0036 0.0047 0 0 0" />
                                        <joint name="iiwa_joint_6" pos="0 0 0" axis="0 0 1" limited="true" range="-2.0943951023931953 2.0943951023931953" damping="0.5"/>
                                        <geom type="mesh" contype="0" conaffinity="0" group="1" mesh="iiwa_link_6_vis" name="iiwa_link_6_visual" rgba="1.0 0.4235294117647059 0.0392156862745098 1.0" />
                                        <geom type="mesh" group="0" mesh="iiwa_link_6" name="iiwa_link_6_collision"/>
                                        <body name="iiwa_link_7" pos="0 0.081 0" quat="0 0 0.7071068 0.7071068">
                                            <inertial pos="0 0 0.02" mass="0.3" fullinertia="0.001 0.001 0.001 0 0 0" />
                                            <joint name="iiwa_joint_7" pos="0 0 0" axis="0 0 1" limited="true" range="-3.0543261909900763 3.0543261909900763" damping="0.5"/>
                                            <geom type="mesh" contype="0" conaffinity="0" group="1" mesh="iiwa_link_7_vis" name="iiwa_link_7_visual" rgba="1.0 0.4235294117647059 0.0392156862745098 1.0" />
                                            <geom type="mesh" group="0" mesh="iiwa_link_7" name="iiwa_link_7_collision"/>
                                            <body name="hand" pos="0 0 0.045" quat="0.7071068 0 0 0.7071068">
                                                <inertial pos="0 0 0" mass="0.5" fullinertia="0.01 0.01 0.01 0.0 0.0 0.0" />
                                                <!-- This camera points out from the eef. -->
                                                <camera mode="fixed" name="iiwa_eye_in_hand" pos="0.05 0 0" fovy="75"/>
                                                <!-- to add gripper -->
                                                <include file="assets/hande.xml"/>
                                            </body>
                                        </body>
                                    </body>
                                </body>
                            </body>
                        </body>
                    </body>
                </body>
            </body>
        </body>
    </worldbody>

    <contact>
        <exclude body1="hande" body2="hande_left_finger" />
        <exclude body1="hande" body2="hande_right_finger" />
    </contact>
    <equality>
        <joint joint1="hande_left_finger_joint" joint2="hande_right_finger_joint" polycoef="0 1 0 0 0" />
    </equality>
    <tendon>
        <fixed name="split">
            <joint joint="hande_left_finger_joint" coef="0.5" />
            <joint joint="hande_right_finger_joint" coef="0.5" />
        </fixed>
    </tendon>
    <actuator>
        <!-- Remap original ctrlrange (0, 0.025) to (0, 255): 0.025 * 100 / 255 = 0.009803922 -->
        <!--
        https://assets.robotiq.com/website-assets/support_documents/document/online/Hand-E_Aubo_InstructionManual_HTML5_20190501.zip/Hand-E_Aubo_InstructionManual_HTML5/Content/6.%20Specifications.htm -->
        <!-- https://mujoco.readthedocs.io/en/stable/XMLreference.html#actuator -->
        <!-- scalar_force = gain_term * (act or ctrl) + bias_term -->
        <!-- gain_term = gain_prm[0] + gain_prm[1]*length + gain_prm[2]*velocity -->
        <!-- bias_term = biasprm[0] + biasprm[1]*length + biasprm[2]*velocity -->
        <general name="hande_fingers_actuator" class="hande" tendon="split" ctrlrange="0 255"
        forcerange="-200 200" gaintype="affine" biastype="affine" gainprm="0.00980392"
        biasprm="0 -100 -10" />
    </actuator>

    <actuator>
        <!-- Physical limits of the actuator. -->
        <motor ctrllimited="true" ctrlrange="-170.0 170.0" joint="iiwa_joint_1" name="iiwa_torq_j1"/>
        <motor ctrllimited="true" ctrlrange="-120.0 120.0" joint="iiwa_joint_2" name="iiwa_torq_j2"/>
        <motor ctrllimited="true" ctrlrange="-170.0 170.0" joint="iiwa_joint_3" name="iiwa_torq_j3"/>
        <motor ctrllimited="true" ctrlrange="-120.0 120.0" joint="iiwa_joint_4" name="iiwa_torq_j4"/>
        <motor ctrllimited="true" ctrlrange="-170.0 170.0" joint="iiwa_joint_5" name="iiwa_torq_j5"/>
        <motor ctrllimited="true" ctrlrange="-120.0 120.0" joint="iiwa_joint_6" name="iiwa_torq_j6"/>
        <motor ctrllimited="true" ctrlrange="-170.0 170.0" joint="iiwa_joint_7" name="iiwa_torq_j7"/>
    </actuator>

</mujocoinclude>
