<?xml version="1.0"?>
<robot xmlns:xacro="http://ros.org/wiki/xacro">
    <xacro:include filename="$(find iiwa_description)/urdf/robotiq_arg2f_transmission.xacro" />

    <xacro:property name="d_value" value="0" />
    <xacro:property name="f_value" value="0" />

    <xacro:macro name="outer_knuckle" params="prefix fingerprefix stroke">
        <link name="${prefix}${fingerprefix}_outer_knuckle">
        <inertial>
            <origin xyz="-0.000200000000003065 0.0199435877845359 0.0292245259211331" rpy="0 0 0" />
            <mass value="0.00853198276973456" />
            <inertia ixx="0.0001" ixy="0.000"  ixz="0.000"  
                     iyy="0.0001" iyz="0.000"
                     izz="0.0001" />
        </inertial>
        <visual>
            <origin xyz="0 0 0" rpy="0 0 0" />
            <geometry>
                <mesh filename="package://iiwa_description/meshes/rq140/robotiq_arg2f_${stroke}_outer_knuckle.stl" />
            </geometry>
            <material name="">
                <color rgba="0.792156862745098 0.819607843137255 0.933333333333333 1" />
            </material>
        </visual>
        <collision>
            <origin xyz="0 0 0" rpy="0 0 0" />
            <geometry>
                <mesh filename="package://iiwa_description/meshes/rq140/robotiq_arg2f_${stroke}_outer_knuckle.stl" />
            </geometry>
        </collision>
        </link>
    </xacro:macro>

    <xacro:macro name="outer_finger" params="prefix fingerprefix stroke">
        <link name="${prefix}${fingerprefix}_outer_finger">
        <inertial>
            <origin xyz="0.00030115855001899 0.0373907951953854 -0.0208027427000385" rpy="0 0 0" />
            <mass value="0.022614240507152" />
            <inertia ixx="0.0001" ixy="0.000"  ixz="0.000"  
                     iyy="0.0001" iyz="0.000"
                     izz="0.0001" />
        </inertial>
        <visual>
            <origin xyz="0 0 0" rpy="0 0 0" />
            <geometry>
                <mesh filename="package://iiwa_description/meshes/rq140/robotiq_arg2f_${stroke}_outer_finger.stl" />
            </geometry>
            <material name="">
                <color rgba="0.1 0.1 0.1 1" />
            </material>
        </visual>
        <collision>
            <origin xyz="0 0 0" rpy="0 0 0" />
            <geometry>
                <mesh filename="package://iiwa_description/meshes/rq140/robotiq_arg2f_${stroke}_outer_finger.stl" />
            </geometry>
        </collision>
        </link>
    </xacro:macro>

    <xacro:macro name="inner_knuckle" params="prefix fingerprefix stroke">
        <link name="${prefix}${fingerprefix}_inner_knuckle">
        <inertial>
            <origin xyz="0.000123011831763771 0.0507850843201817 0.00103968640075166" rpy="0 0 0" />
            <mass value="0.0271177346495152" />
            <inertia ixx="0.0001" ixy="0.000"  ixz="0.000"  
                     iyy="0.0001" iyz="0.000"
                     izz="0.0001" />
        </inertial>
        <visual>
            <origin xyz="0 0 0" rpy="0 0 0" />
            <geometry>
                <mesh filename="package://iiwa_description/meshes/rq140/robotiq_arg2f_${stroke}_inner_knuckle.stl" />
            </geometry>
            <material name="">
                <color rgba="0.1 0.1 0.1 1" />
            </material>
        </visual>
        <collision>
            <origin xyz="0 0 0" rpy="0 0 0" />
            <geometry>
                <mesh filename="package://iiwa_description/meshes/rq140/robotiq_arg2f_${stroke}_inner_knuckle.stl" />
            </geometry>
        </collision>
        </link>
    </xacro:macro>

    <xacro:macro name="inner_finger" params="prefix fingerprefix stroke">
        <link name="${prefix}${fingerprefix}_inner_finger">
        <inertial>
            <origin xyz="0.000299999999999317 0.0160078233491243 -0.0136945669206257" rpy="0 0 0" />
            <mass value="0.0104003125914103" />
            <inertia ixx="0.0001" ixy="0.000"  ixz="0.000"  
                     iyy="0.0001" iyz="0.000"
                     izz="0.0001" />
        </inertial>
        <visual>
            <origin xyz="0 0 0" rpy="0 0 0" />
            <geometry>
                <mesh filename="package://iiwa_description/meshes/rq140/robotiq_arg2f_${stroke}_inner_finger.stl" />
            </geometry>
            <material name="">
                <color rgba="0.1 0.1 0.1 1" />
            </material>
        </visual>
        <collision>
            <origin xyz="0 0 0" rpy="0 0 0" />
            <geometry>
                <mesh filename="package://iiwa_description/meshes/rq140/robotiq_arg2f_${stroke}_inner_finger.stl" />
            </geometry>
        </collision>
        </link>
        <gazebo reference="${prefix}${fingerprefix}_inner_finger">
            <kp>1000000.0</kp>
            <kd>1.0</kd>
            <mu1>1.0</mu1>
            <mu2>1.0</mu2>
            <minDepth>0.001</minDepth>
        </gazebo>
    </xacro:macro>

    <xacro:macro name="outer_finger_joint" params="prefix fingerprefix">
        <joint name="${prefix}${fingerprefix}_outer_finger_joint" type="fixed">
            <origin xyz="0 0.01821998610742 0.0260018192872234" rpy="0 0 0" />
            <parent link="${prefix}${fingerprefix}_outer_knuckle" />
            <child link="${prefix}${fingerprefix}_outer_finger" />
            <axis xyz="1 0 0" />
        </joint>
    </xacro:macro>

    <xacro:macro name="inner_knuckle_joint" params="prefix fingerprefix reflect">
        <joint name="${prefix}${fingerprefix}_inner_knuckle_joint" type="revolute">
            <origin xyz="0 ${reflect * -0.0127} 0.06142" rpy="${pi / 2 + 0.9} 0 ${(reflect - 1) * pi / 2}" />
            <parent link="${prefix}robotiq_arg2f_base_link" />
            <child link="${prefix}${fingerprefix}_inner_knuckle" />
            <axis xyz="1 0 0" />
            <!--<limit lower="0" upper="0.8757" velocity="100" effort="1000" /> -->
            <limit lower="-3.14159" upper="3.14159" velocity="100" effort="1000" /> 
            <mimic joint="${prefix}finger_joint" multiplier="-1" offset="0" />
            <dynamics damping="${d_value}" friction="${f_value}"/>
        </joint>
    </xacro:macro>

    <xacro:macro name="inner_finger_joint" params="prefix fingerprefix">
        <joint name="${prefix}${fingerprefix}_inner_finger_joint" type="revolute">
            <origin xyz="0 0.0817554015893473 -0.0282203446692936" rpy="-0.9 0 0" />
            <parent link="${prefix}${fingerprefix}_outer_finger" />
            <child link="${prefix}${fingerprefix}_inner_finger" />
            <axis xyz="1 0 0" />
            <limit lower="-3.14159" upper="3.14159" velocity="100" effort="1000" />
            <!-- <limit lower="0" upper="0.8757" velocity="100" effort="1000" /> -->
            <mimic joint="${prefix}finger_joint" multiplier="1" offset="0" />
            <dynamics damping="${d_value}" friction="${f_value}"/>
        </joint>
    </xacro:macro>

    <xacro:macro name="finger_joint" params="prefix">
        <joint name="${prefix}finger_joint" type="revolute">
            <origin xyz="0 -0.030601 0.054905" rpy="${pi / 2 + 0.9} 0 0" />
            <parent link="${prefix}robotiq_arg2f_base_link" />
            <child link="${prefix}left_outer_knuckle" />
            <axis xyz="-1 0 0" />
            <!-- <limit lower="-3.14159" upper="3.14159" velocity="100" effort="1000" /> -->
            <limit lower="0" upper="0.775" velocity="100" effort="1000" /> 
            <dynamics damping="${d_value}" friction="${f_value}"/>
        </joint>
        <xacro:finger_joints prefix="${prefix}" fingerprefix="left" reflect="1.0"/>
    </xacro:macro>

    <xacro:macro name="right_outer_knuckle_joint" params="prefix">
        <joint name="${prefix}right_outer_knuckle_joint" type="revolute">
            <origin xyz="0 0.030601 0.054905" rpy="${pi / 2 + 0.9} 0 ${pi}" />
            <parent link="${prefix}robotiq_arg2f_base_link" />
            <child link="${prefix}right_outer_knuckle" />
            <axis xyz="1 0 0" />
            <!-- <limit lower="0" upper="0.725" velocity="100" effort="1000" /> -->
            <limit lower="-3.14159" upper="3.14159" velocity="100" effort="1000" /> 
            <mimic joint="${prefix}finger_joint" multiplier="-1" offset="0" />
            <dynamics damping="${d_value}" friction="${f_value}"/>
        </joint>
        <xacro:finger_joints prefix="${prefix}" fingerprefix="right" reflect="-1.0"/>
    </xacro:macro>

    <!--finger tip-->
    <xacro:macro name="finger_tip" params="prefix fingerprefix stroke">
        <link name="${prefix}${fingerprefix}_finger_tip">
        <inertial>
            <origin xyz="0.000299999999999317 0.0160078233491243 -0.0136945669206257" rpy="0 0 0" />
            <mass value="0.0104003125914103" />
            <inertia ixx="0.0001" ixy="0.000"  ixz="0.000"  
                     iyy="0.0001" iyz="0.000"
                     izz="0.0001" />
        </inertial>
        <visual>
            <origin xyz="0 0.02 -0.05" rpy="0 0 0" />
            <geometry>
                <mesh filename="package://iiwa_description/meshes/rq140/robotiq_arg2f_${stroke}_finger_tip.dae" scale="1.0 1.0 1.0"/>
            </geometry>
            <material name="">
                <color rgba="0.1 0.1 0.1 1" />
            </material>
        </visual>
        <collision>
            <origin xyz="0 0.02 -0.05" rpy="0 0 0" />
            <geometry>
                <mesh filename="package://iiwa_description/meshes/rq140/robotiq_arg2f_${stroke}_finger_tip.dae" scale="1.0 1.0 1.0"/>
            </geometry>
        </collision>
        </link>
        <gazebo reference="${prefix}${fingerprefix}_finger_tip">
            <kp>1000000.0</kp>
            <kd>1.0</kd>
            <mu1>1.0</mu1>
            <mu2>1.0</mu2>
            <minDepth>0.001</minDepth>
        </gazebo>
    </xacro:macro>

    <xacro:macro name="finger_tip_joint" params="prefix fingerprefix">
        <joint name="${prefix}${fingerprefix}_finger_tip_joint" type="fixed">
            <origin xyz="0 0.01821998610742 0.0260018192872234" rpy="0 0 0" />
            <parent link="${prefix}${fingerprefix}_inner_finger" />
            <child link="${prefix}${fingerprefix}_finger_tip" />
            <axis xyz="1 0 0" />
        </joint>
    </xacro:macro>

        <!--Import robotiq desciptions-->
    <xacro:include filename="$(find iiwa_description)/urdf/robotiq_arg2f.xacro" />

    <xacro:macro name="robotiq_arg2f_140" params="prefix">
        <xacro:robotiq_arg2f_base_link prefix="${prefix}"/>
        <xacro:finger_links prefix="${prefix}" fingerprefix="left" stroke="140"/>
        <xacro:finger_links prefix="${prefix}" fingerprefix="right" stroke="140"/>
        <xacro:finger_joint prefix="${prefix}"/>
        <xacro:right_outer_knuckle_joint prefix="${prefix}"/>
        <xacro:robotiq_arg2f_transmission prefix="${prefix}"/>
    </xacro:macro>
</robot>
